<?xml version='1.0' encoding='utf-8'?>
<robot name="mickrobot">
  <link name="base_footprint">
    <visual>
      <geometry>
        <sphere radius="0.001" />
      </geometry>
      <material name="invisible">
        <color rgba="0 0 0 0" />
      </material>
    </visual>
  </link>
  <joint name="base_joint" type="fixed">
    <parent link="base_footprint" />
    <child link="base_link" />
    <origin xyz="0 0 0" rpy="0 0 0" />
  </joint>
  <link name="top_payload_link">
    <visual>
      <origin xyz="0 0 0" rpy="0 0 0" />
      <geometry>
        <mesh filename="package://mickrobot_description/urdf/mesh/board_camera_radar_assembly.stl" scale="1 1 1" />
      </geometry>
      <material name="payload_dark">
        <color rgba="0.08 0.08 0.08 1" />
      </material>
    </visual>
    <collision>
      <origin xyz="0 0 0.0165" rpy="0 0 0" />
      <geometry>
        <box size="0.07 0.104 0.033" />
      </geometry>
    </collision>
    <inertial>
      <mass value="0.2" />
      <origin xyz="0 0 0.0165" rpy="0 0 0" />
      <inertia ixx="1e-4" ixy="0" ixz="0" iyy="1e-4" iyz="0" izz="1e-4" />
    </inertial>
  </link>
  <joint name="top_payload_joint" type="fixed">
    <parent link="base_link" />
    <child link="top_payload_link" />
    <origin xyz="0 0 0.128031" rpy="0 0 0" />
  </joint>
  <link name="base_link">
    <visual>
      <origin xyz="0 0 0.082" rpy="0 0 0" />
      <geometry>
        <mesh filename="package://mickrobot_description/urdf/mesh/ugv01_body.STL" scale="0.001 0.001 0.001" />
      </geometry>
      <material name="chassis_gray">
        <color rgba="0.3 0.3 0.3 1" />
      </material>
    </visual>
    <collision>
      <origin xyz="0 0 0.07" rpy="0 0 0" />
      <geometry>
        <box size="0.253 0.23 0.14" />
      </geometry>
    </collision>
    <inertial>
      <mass value="5" />
      <origin xyz="0 0 0.065" rpy="0 0 0" />
      <inertia ixx="0.02" ixy="0" ixz="0" iyy="0.03" iyz="0" izz="0.04" />
    </inertial>
  </link>
  <link name="right_back_wheel">
    <visual>
      <origin xyz="0 0 0" rpy="1.57079 0 0" />
      <geometry>
        <cylinder radius="0.04" length="0.03" />
      </geometry>
      <material name="wheel_black">
        <color rgba="0.1 0.1 0.1 1" />
      </material>
    </visual>
    <collision>
      <origin xyz="0 0 0" rpy="1.57079 0 0" />
      <geometry>
        <cylinder radius="0.04" length="0.03" />
      </geometry>
    </collision>
    <inertial>
      <mass value="0.5" />
      <origin xyz="0 0 0" rpy="1.57079 0 0" />
      <inertia ixx="0.00024" ixy="0" ixz="0" iyy="0.00024" iyz="0" izz="0.0004" />
    </inertial>
  </link>
  <joint name="right_back_wheel_joint" type="continuous">
    <axis xyz="0 1 0" />
    <parent link="base_link" />
    <child link="right_back_wheel" />
    <origin xyz="-0.086 -0.09 0.04" />
    <limit effort="100" velocity="100" />
    <dynamics damping="0.1" friction="0.05" />
  </joint>
  <link name="right_front_wheel">
    <visual>
      <origin xyz="0 0 0" rpy="1.57079 0 0" />
      <geometry>
        <cylinder radius="0.04" length="0.03" />
      </geometry>
      <material name="wheel_black">
        <color rgba="0.1 0.1 0.1 1" />
      </material>
    </visual>
    <collision>
      <origin xyz="0 0 0" rpy="1.57079 0 0" />
      <geometry>
        <cylinder radius="0.04" length="0.03" />
      </geometry>
    </collision>
    <inertial>
      <mass value="0.5" />
      <origin xyz="0 0 0" rpy="1.57079 0 0" />
      <inertia ixx="0.00024" ixy="0" ixz="0" iyy="0.00024" iyz="0" izz="0.0004" />
    </inertial>
  </link>
  <joint name="right_front_wheel_joint" type="continuous">
    <axis xyz="0 1 0" />
    <parent link="base_link" />
    <child link="right_front_wheel" />
    <origin xyz="0.086 -0.09 0.04" />
    <limit effort="100" velocity="100" />
    <dynamics damping="0.1" friction="0.05" />
  </joint>
  <link name="left_back_wheel">
    <visual>
      <origin xyz="0 0 0" rpy="1.57079 0 0" />
      <geometry>
        <cylinder radius="0.04" length="0.03" />
      </geometry>
      <material name="wheel_black">
        <color rgba="0.1 0.1 0.1 1" />
      </material>
    </visual>
    <collision>
      <origin xyz="0 0 0" rpy="1.57079 0 0" />
      <geometry>
        <cylinder radius="0.04" length="0.03" />
      </geometry>
    </collision>
    <inertial>
      <mass value="0.5" />
      <origin xyz="0 0 0" rpy="1.57079 0 0" />
      <inertia ixx="0.00024" ixy="0" ixz="0" iyy="0.00024" iyz="0" izz="0.0004" />
    </inertial>
  </link>
  <joint name="left_back_wheel_joint" type="continuous">
    <axis xyz="0 1 0" />
    <parent link="base_link" />
    <child link="left_back_wheel" />
    <origin xyz="-0.086 0.09 0.04" />
    <limit effort="100" velocity="100" />
    <dynamics damping="0.1" friction="0.05" />
  </joint>
  <link name="left_front_wheel">
    <visual>
      <origin xyz="0 0 0" rpy="1.57079 0 0" />
      <geometry>
        <cylinder radius="0.04" length="0.03" />
      </geometry>
      <material name="wheel_black">
        <color rgba="0.1 0.1 0.1 1" />
      </material>
    </visual>
    <collision>
      <origin xyz="0 0 0" rpy="1.57079 0 0" />
      <geometry>
        <cylinder radius="0.04" length="0.03" />
      </geometry>
    </collision>
    <inertial>
      <mass value="0.5" />
      <origin xyz="0 0 0" rpy="1.57079 0 0" />
      <inertia ixx="0.00024" ixy="0" ixz="0" iyy="0.00024" iyz="0" izz="0.0004" />
    </inertial>
  </link>
  <joint name="left_front_wheel_joint" type="continuous">
    <axis xyz="0 1 0" />
    <parent link="base_link" />
    <child link="left_front_wheel" />
    <origin xyz="0.086 0.09 0.04" />
    <limit effort="100" velocity="100" />
    <dynamics damping="0.1" friction="0.05" />
  </joint>
  <link name="right_mid_wheel">
    <visual>
      <origin xyz="0 0 0" rpy="1.57079 0 0" />
      <geometry>
        <cylinder radius="0.04" length="0.03" />
      </geometry>
      <material name="wheel_black">
        <color rgba="0.1 0.1 0.1 1" />
      </material>
    </visual>
    <collision>
      <origin xyz="0 0 0" rpy="1.57079 0 0" />
      <geometry>
        <cylinder radius="0.04" length="0.03" />
      </geometry>
    </collision>
    <inertial>
      <mass value="0.5" />
      <origin xyz="0 0 0" rpy="1.57079 0 0" />
      <inertia ixx="0.00024" ixy="0" ixz="0" iyy="0.00024" iyz="0" izz="0.0004" />
    </inertial>
  </link>
  <joint name="right_mid_wheel_joint" type="continuous">
    <axis xyz="0 1 0" />
    <parent link="base_link" />
    <child link="right_mid_wheel" />
    <origin xyz="0.000 -0.09 0.04" />
    <limit effort="100" velocity="100" />
    <dynamics damping="0.05" friction="0.02" />
  </joint>
  <link name="left_mid_wheel">
    <visual>
      <origin xyz="0 0 0" rpy="1.57079 0 0" />
      <geometry>
        <cylinder radius="0.04" length="0.03" />
      </geometry>
      <material name="wheel_black">
        <color rgba="0.1 0.1 0.1 1" />
      </material>
    </visual>
    <collision>
      <origin xyz="0 0 0" rpy="1.57079 0 0" />
      <geometry>
        <cylinder radius="0.04" length="0.03" />
      </geometry>
    </collision>
    <inertial>
      <mass value="0.5" />
      <origin xyz="0 0 0" rpy="1.57079 0 0" />
      <inertia ixx="0.00024" ixy="0" ixz="0" iyy="0.00024" iyz="0" izz="0.0004" />
    </inertial>
  </link>
  <joint name="left_mid_wheel_joint" type="continuous">
    <axis xyz="0 1 0" />
    <parent link="base_link" />
    <child link="left_mid_wheel" />
    <origin xyz="0.000 0.09 0.04" />
    <limit effort="100" velocity="100" />
    <dynamics damping="0.05" friction="0.02" />
  </joint>
  <link name="imu_link">
    <visual>
      <geometry>
        <box size="0.04 0.04 0.015" />
      </geometry>
    </visual>
    <collision>
      <geometry>
        <box size="0.04 0.04 0.015" />
      </geometry>
    </collision>
    <inertial>
      <mass value="0.1" />
      <inertia ixx="3.333e-6" ixy="0" ixz="0" iyy="3.333e-6" iyz="0" izz="3.333e-6" />
    </inertial>
  </link>
  <joint name="imu_joint" type="fixed">
    <parent link="base_link" />
    <child link="imu_link" />
    <origin xyz="0 0 0.09" rpy="0 0 0" />
  </joint>
  <link name="laser_link">
    <visual>
      <origin xyz="0 0 0" rpy="0 0 0" />
      <geometry>
        <box size="0.038 0.038 0.012" />
      </geometry>
      <material name="lidar_base_blue">
        <color rgba="0.05 0.05 1.0 1" />
      </material>
    </visual>
    <collision>
      <origin xyz="0 0 0" rpy="0 0 0" />
      <geometry>
        <box size="0.038 0.038 0.012" />
      </geometry>
    </collision>
    <inertial>
      <mass value="0.2" />
      <inertia ixx="3.333e-5" ixy="0" ixz="0" iyy="3.333e-5" iyz="0" izz="3.333e-5" />
    </inertial>
  </link>
  <joint name="laser_joint" type="fixed">
    <parent link="base_link" />
    <child link="laser_link" />
    <origin xyz="-0.0135 0 0.158031" rpy="0 0 0" />
  </joint>
  <link name="camera_left_link">
    <visual>
      <origin xyz="0 0 0" rpy="0 0 0" />
      <geometry>
        <box size="0.001 0.001 0.001" />
      </geometry>
      <material name="sensor_frame_invisible">
        <color rgba="0 0 0 0" />
      </material>
    </visual>
    <collision>
      <origin xyz="0 0 0" rpy="0 0 0" />
      <geometry>
        <box size="0.001 0.001 0.001" />
      </geometry>
    </collision>
    <inertial>
      <mass value="0.001" />
      <inertia ixx="1e-9" ixy="0" ixz="0" iyy="1e-9" iyz="0" izz="1e-9" />
    </inertial>
  </link>
  <joint name="camera_left_joint" type="fixed">
    <parent link="base_link" />
    <child link="camera_left_link" />
    <origin xyz="0.0357 0.007274 0.149031" rpy="0 0 0" />
  </joint>
  <link name="camera_rgb_link">
    <visual>
      <origin xyz="0 0 0" rpy="0 0 0" />
      <geometry>
        <box size="0.001 0.001 0.001" />
      </geometry>
      <material name="sensor_frame_invisible">
        <color rgba="0 0 0 0" />
      </material>
    </visual>
    <collision>
      <origin xyz="0 0 0" rpy="0 0 0" />
      <geometry>
        <box size="0.001 0.001 0.001" />
      </geometry>
    </collision>
    <inertial>
      <mass value="0.001" />
      <inertia ixx="1e-9" ixy="0" ixz="0" iyy="1e-9" iyz="0" izz="1e-9" />
    </inertial>
  </link>
  <joint name="camera_rgb_joint" type="fixed">
    <parent link="base_link" />
    <child link="camera_rgb_link" />
    <origin xyz="0.0357 -0.0305 0.149031" rpy="0 0 0" />
  </joint>
  <link name="camera_right_link">
    <visual>
      <origin xyz="0 0 0" rpy="0 0 0" />
      <geometry>
        <box size="0.001 0.001 0.001" />
      </geometry>
      <material name="sensor_frame_invisible">
        <color rgba="0 0 0 0" />
      </material>
    </visual>
    <collision>
      <origin xyz="0 0 0" rpy="0 0 0" />
      <geometry>
        <box size="0.001 0.001 0.001" />
      </geometry>
    </collision>
    <inertial>
      <mass value="0.001" />
      <inertia ixx="1e-9" ixy="0" ixz="0" iyy="1e-9" iyz="0" izz="1e-9" />
    </inertial>
  </link>
  <joint name="camera_right_joint" type="fixed">
    <parent link="base_link" />
    <child link="camera_right_link" />
    <origin xyz="0.0357 -0.068274 0.149031" rpy="0 0 0" />
  </joint>
</robot>